<?xml version="1.0" ?>
<!-- =================================================================================== -->
<!-- |    This document was autogenerated by xacro from model.sdf.xacro                | -->
<!-- |    EDITING THIS FILE BY HAND IS NOT RECOMMENDED                                 | -->
<!-- =================================================================================== -->
<sdf version="1.4">
  <model name="mobot" xmlns:xacro="http://www.ros.org/wiki/xacro">
    <static>false</static>
    <link name="chassis">
      <pose>0 0 0.1 0 0 0</pose>
      <collision name="collision">
        <geometry>
          <box>
            <size>0.4 0.2 0.1</size>
          </box>
        </geometry>
      </collision>
      <visual name="visual">
        <geometry>
          <box>
            <size>0.4 0.2 0.1</size>
          </box>
        </geometry>
        <material>
          <script>
            <name>Gazebo/Orange</name>
            <uri>__default__</uri>
          </script>
        </material>
      </visual>
      <inertial>
        <mass>50</mass>
        <inertia>
          <ixx>0.208333333333</ixx>
          <iyy>0.708333333333</iyy>
          <izz>0.833333333333</izz>
          <ixy>0</ixy>
          <ixz>0</ixz>
          <iyz>0</iyz>
        </inertia>
      </inertial>
      <collision name="caster_collision">
        <pose>-0.133333333333 0 -0.05 0 0 0</pose>
        <geometry>
          <sphere>
            <radius>0.05</radius>
          </sphere>
        </geometry>
        <surface>
          <friction>
            <ode>
              <mu>0</mu>
              <mu2>0</mu2>
              <slip1>1.0</slip1>
              <slip2>1.0</slip2>
            </ode>
          </friction>
        </surface>
      </collision>
      <visual name="caster_visual">
        <pose>-0.133333333333 0 -0.05 0 0 0</pose>
        <geometry>
          <sphere>
            <radius>0.05</radius>
          </sphere>
        </geometry>
        <material>
          <script>
            <name>Gazebo/Red</name>
            <uri>__default__</uri>
          </script>
        </material>
      </visual>
    </link>
    <joint name="camera_joint" type="revolute">
      <child>camera_link</child>
      <parent>chassis</parent>
      <axis>
        <xyz>0 0 1</xyz>
        <limit>
          <upper>0</upper>
          <lower>0</lower>
        </limit>
      </axis>
    </joint>
    <link name="camera_link">
      <pose>0.175 0 0.175 0 0 0</pose>
      <inertial>
        <mass>0.1</mass>
        <inertia>
          <ixx>4.16666666667e-05</ixx>
          <iyy>4.16666666667e-05</iyy>
          <izz>4.16666666667e-05</izz>
          <ixy>0</ixy>
          <ixz>0</ixz>
          <iyz>0</iyz>
        </inertia>
      </inertial>
      <collision name="camera_collision">
        <geometry>
          <box>
            <size>0.05 0.05 0.05</size>
          </box>
        </geometry>
      </collision>
      <visual name="camera_visual">
        <geometry>
          <box>
            <size>0.05 0.05 0.05</size>
          </box>
        </geometry>
        <material>
          <script>
            <name>Gazebo/Red</name>
            <uri>__default__</uri>
          </script>
        </material>
      </visual>
      <sensor name="camera1" type="camera">
        <update_rate>30</update_rate>
        <camera name="head">
          <horizontal_fov>1.39626</horizontal_fov>
          <image>
            <width>800</width>
            <height>800</height>
            <format>R8G8B8</format>
          </image>
          <clip>
            <near>0.02</near>
            <far>300</far>
          </clip>
          <noise>
            <type>gaussian</type>
            <mean>0</mean>
            <stddev>0.007</stddev>
          </noise>
        </camera>
        <plugin filename="libgazebo_ros_camera.so" name="camera_controller">
          <alwaysOn>true</alwaysOn>
          <updateRate>0.0</updateRate>
          <cameraName>mobot/camera1</cameraName>
          <imageTopicName>image_raw</imageTopicName>
          <cameraInfoTopicName>camera_info</cameraInfoTopicName>
          <frameName>camera_link</frameName>
          <hackBaseline>0.07</hackBaseline>
          <distortionK1>0.0</distortionK1>
          <distortionK2>0.0</distortionK2>
          <distortionK3>0.0</distortionK3>
          <distortionT1>0.0</distortionT1>
          <distortionT2>0.0</distortionT2>
        </plugin>
        <pose>0.175 0 0.175 0 -0 0</pose>
      </sensor>
    </link>
    <link name="left_wheel">
      <pose>0.12 0.125 0.1 0 1.57079632679 1.57079632679</pose>
      <collision name="left_wheel_collision">
        <geometry>
          <cylinder>
            <radius>0.1</radius>
            <length>0.05</length>
          </cylinder>
        </geometry>
        <surface>
          <friction>
            <ode>
              <mu>1.0</mu>
              <mu2>1.0</mu2>
              <slip1>0.0</slip1>
              <slip2>0.0</slip2>
            </ode>
          </friction>
        </surface>
      </collision>
      <visual name="left_wheel_visual">
        <geometry>
          <cylinder>
            <radius>0.1</radius>
            <length>0.05</length>
          </cylinder>
        </geometry>
        <material>
          <script>
            <name>Gazebo/Black</name>
            <uri>__default__</uri>
          </script>
        </material>
      </visual>
      <inertial>
        <mass>5</mass>
        <inertia>
          <ixx>0.0135416666667</ixx>
          <iyy>0.0135416666667</iyy>
          <izz>0.025</izz>
          <ixy>0</ixy>
          <ixz>0</ixz>
          <iyz>0</iyz>
        </inertia>
      </inertial>
    </link>
    <joint name="left_wheel_hinge" type="revolute">
      <parent>chassis</parent>
      <child>left_wheel</child>
      <pose>0 0 0.025 0 0 0</pose>
      <axis>
        <xyz>0 1 0</xyz>
        <dynamics>
          <damping>5</damping>
        </dynamics>
        <limit>
          <effort>100</effort>
          <velocity>100</velocity>
        </limit>
      </axis>
    </joint>
    <link name="right_wheel">
      <pose>0.12 -0.125 0.1 0 1.57079632679 1.57079632679</pose>
      <collision name="right_wheel_collision">
        <geometry>
          <cylinder>
            <radius>0.1</radius>
            <length>0.05</length>
          </cylinder>
        </geometry>
        <surface>
          <friction>
            <ode>
              <mu>1.0</mu>
              <mu2>1.0</mu2>
              <slip1>0.0</slip1>
              <slip2>0.0</slip2>
            </ode>
          </friction>
        </surface>
      </collision>
      <visual name="right_wheel_visual">
        <geometry>
          <cylinder>
            <radius>0.1</radius>
            <length>0.05</length>
          </cylinder>
        </geometry>
        <material>
          <script>
            <name>Gazebo/Black</name>
            <uri>__default__</uri>
          </script>
        </material>
      </visual>
      <inertial>
        <mass>5</mass>
        <inertia>
          <ixx>0.0135416666667</ixx>
          <iyy>0.0135416666667</iyy>
          <izz>0.025</izz>
          <ixy>0</ixy>
          <ixz>0</ixz>
          <iyz>0</iyz>
        </inertia>
      </inertial>
    </link>
    <joint name="right_wheel_hinge" type="revolute">
      <parent>chassis</parent>
      <child>right_wheel</child>
      <pose>0 0 0.025 0 0 0</pose>
      <axis>
        <xyz>0 1 0</xyz>
        <dynamics>
          <damping>5</damping>
        </dynamics>
        <limit>
          <effort>100</effort>
          <velocity>100</velocity>
        </limit>
      </axis>
    </joint>
    <plugin filename="libgazebo_ros_diff_drive.so" name="differential_drive_controller">
      <alwaysOn>true</alwaysOn>
      <updateRate>100</updateRate>
      <leftJoint>left_wheel_hinge</leftJoint>
      <rightJoint>right_wheel_hinge</rightJoint>
      <wheelSeparation>0.25</wheelSeparation>
      <wheelDiameter>0.2</wheelDiameter>
      <torque>20</torque>
      <commandTopic>mobot/cmd_vel</commandTopic>
      <odometryTopic>mobot/odom_diffdrive</odometryTopic>
      <odometryFrame>odom</odometryFrame>
      <robotBaseFrame>chassis</robotBaseFrame>
    </plugin>
  </model>
</sdf>
